2023-04-20T13:40:31 [     708] INFO    : client          @run              #709  : Received signal to terminate bot and event loop.
2023-04-20T13:40:31 [     708] INFO    : client          @run              #712  : Cleaning up tasks.
2023-04-20T13:40:31 [     708] INFO    : client          @_cancel_tasks    #86   : Cleaning up after 1 tasks.
2023-04-20T13:40:31 [     836] INFO    : client          @_cancel_tasks    #91   : All tasks finished cancelling.
2023-04-20T13:40:31 [     837] INFO    : client          @_cleanup_loop    #111  : Closing the event loop.
2023-04-20T13:40:33 [     702] WARNING : client          @__init__         #252  : PyNaCl is not installed, voice will NOT be supported
2023-04-20T13:40:33 [     703] INFO    : client          @login            #512  : logging in using static token
2023-04-20T13:40:34 [     357] INFO    : gateway         @identify         #430  : Shard ID None has sent the IDENTIFY payload.
2023-04-20T13:40:34 [     657] INFO    : gateway         @received_message #524  : Shard ID None has connected to Gateway: ["gateway-prd-us-east1-b-9g36",{"micros":158133,"calls":["id_created",{"micros":2360,"calls":[]},"session_lookup_time",{"micros":269,"calls":[]},"session_lookup_finished",{"micros":15,"calls":[]},"discord-sessions-prd-2-58",{"micros":153238,"calls":["start_session",{"micros":99890,"calls":["discord-api-d8b49b74b-8jv4c",{"micros":85124,"calls":["get_user",{"micros":17371},"get_guilds",{"micros":11497},"send_scheduled_deletion_message",{"micros":9},"guild_join_requests",{"micros":4610},"authorized_ip_coro",{"micros":9}]}]},"starting_guild_connect",{"micros":46,"calls":[]},"presence_started",{"micros":180,"calls":[]},"guilds_started",{"micros":81,"calls":[]},"guilds_connect",{"micros":1,"calls":[]},"presence_connect",{"micros":52991,"calls":[]},"connect_finished",{"micros":52996,"calls":[]},"build_ready",{"micros":20,"calls":[]},"clean_ready",{"micros":1,"calls":[]},"optimize_ready",{"micros":22,"calls":[]},"split_ready",{"micros":1,"calls":[]}]}]}] (Session ID: d9075a9f46bb1f2c559e968eb4fbdb65).
2023-04-20T13:54:41 [     289] INFO    : client          @run              #709  : Received signal to terminate bot and event loop.
2023-04-20T13:54:41 [     290] INFO    : client          @run              #712  : Cleaning up tasks.
2023-04-20T13:54:41 [     290] INFO    : client          @_cancel_tasks    #86   : Cleaning up after 1 tasks.
2023-04-20T13:54:41 [     408] INFO    : client          @_cancel_tasks    #91   : All tasks finished cancelling.
2023-04-20T13:54:41 [     410] INFO    : client          @_cleanup_loop    #111  : Closing the event loop.
2023-04-20T13:54:43 [     556] WARNING : client          @__init__         #252  : PyNaCl is not installed, voice will NOT be supported
2023-04-20T13:54:43 [     605] INFO    : client          @login            #512  : logging in using static token
2023-04-20T13:54:44 [     278] INFO    : gateway         @identify         #430  : Shard ID None has sent the IDENTIFY payload.
2023-04-20T13:54:44 [     496] INFO    : gateway         @received_message #524  : Shard ID None has connected to Gateway: ["gateway-prd-us-east1-c-vr0k",{"micros":108818,"calls":["id_created",{"micros":1348,"calls":[]},"session_lookup_time",{"micros":314,"calls":[]},"session_lookup_finished",{"micros":14,"calls":[]},"discord-sessions-prd-2-110",{"micros":106540,"calls":["start_session",{"micros":67057,"calls":["discord-api-d8b49b74b-4chkk",{"micros":60342,"calls":["get_user",{"micros":13114},"get_guilds",{"micros":5736},"send_scheduled_deletion_message",{"micros":10},"guild_join_requests",{"micros":1},"authorized_ip_coro",{"micros":11}]}]},"starting_guild_connect",{"micros":51,"calls":[]},"presence_started",{"micros":266,"calls":[]},"guilds_started",{"micros":67,"calls":[]},"guilds_connect",{"micros":1,"calls":[]},"presence_connect",{"micros":39048,"calls":[]},"connect_finished",{"micros":39052,"calls":[]},"build_ready",{"micros":17,"calls":[]},"clean_ready",{"micros":0,"calls":[]},"optimize_ready",{"micros":28,"calls":[]},"split_ready",{"micros":1,"calls":[]}]}]}] (Session ID: 70d6d4d5beac7a44081f29e3f1cd4ed9).
2023-04-20T13:55:07 [     201] INFO    : client          @run              #709  : Received signal to terminate bot and event loop.
2023-04-20T13:55:07 [     201] INFO    : client          @run              #712  : Cleaning up tasks.
2023-04-20T13:55:07 [     203] INFO    : client          @_cancel_tasks    #86   : Cleaning up after 1 tasks.
2023-04-20T13:55:07 [     311] INFO    : client          @_cancel_tasks    #91   : All tasks finished cancelling.
2023-04-20T13:55:07 [     311] INFO    : client          @_cleanup_loop    #111  : Closing the event loop.
2023-04-20T13:56:04 [     122] WARNING : client          @__init__         #252  : PyNaCl is not installed, voice will NOT be supported
2023-04-20T13:56:04 [     158] INFO    : client          @login            #512  : logging in using static token
2023-04-20T13:56:04 [     765] INFO    : gateway         @identify         #430  : Shard ID None has sent the IDENTIFY payload.
2023-04-20T13:56:05 [     160] INFO    : gateway         @received_message #524  : Shard ID None has connected to Gateway: ["gateway-prd-us-east1-d-zk2f",{"micros":249586,"calls":["id_created",{"micros":920,"calls":[]},"session_lookup_time",{"micros":6110,"calls":[]},"session_lookup_finished",{"micros":18,"calls":[]},"discord-sessions-prd-2-3",{"micros":242225,"calls":["start_session",{"micros":192262,"calls":["discord-api-d8b49b74b-hh86q",{"micros":183838,"calls":["get_user",{"micros":30809},"get_guilds",{"micros":17445},"send_scheduled_deletion_message",{"micros":11},"guild_join_requests",{"micros":6726},"authorized_ip_coro",{"micros":10}]}]},"starting_guild_connect",{"micros":51,"calls":[]},"presence_started",{"micros":224,"calls":[]},"guilds_started",{"micros":53,"calls":[]},"guilds_connect",{"micros":1,"calls":[]},"presence_connect",{"micros":49584,"calls":[]},"connect_finished",{"micros":49589,"calls":[]},"build_ready",{"micros":15,"calls":[]},"clean_ready",{"micros":1,"calls":[]},"optimize_ready",{"micros":27,"calls":[]},"split_ready",{"micros":1,"calls":[]}]}]}] (Session ID: efc338069e9e386cbcf586be0f941e49).
2023-04-20T13:57:31 [      95] INFO    : client          @run              #709  : Received signal to terminate bot and event loop.
2023-04-20T13:57:31 [      95] INFO    : client          @run              #712  : Cleaning up tasks.
2023-04-20T13:57:31 [      95] INFO    : client          @_cancel_tasks    #86   : Cleaning up after 1 tasks.
2023-04-20T13:57:31 [     210] INFO    : client          @_cancel_tasks    #91   : All tasks finished cancelling.
2023-04-20T13:57:31 [     211] INFO    : client          @_cleanup_loop    #111  : Closing the event loop.
2023-04-20T13:57:40 [     703] WARNING : client          @__init__         #252  : PyNaCl is not installed, voice will NOT be supported
2023-04-20T13:57:40 [     777] INFO    : client          @login            #512  : logging in using static token
2023-04-20T13:57:41 [     330] INFO    : gateway         @identify         #430  : Shard ID None has sent the IDENTIFY payload.
2023-04-20T13:57:41 [     503] INFO    : gateway         @received_message #524  : Shard ID None has connected to Gateway: ["gateway-prd-us-east1-b-gj4b",{"micros":63676,"calls":["id_created",{"micros":933,"calls":[]},"session_lookup_time",{"micros":7619,"calls":[]},"session_lookup_finished",{"micros":19,"calls":[]},"discord-sessions-prd-2-1",{"micros":54079,"calls":["start_session",{"micros":40540,"calls":["discord-api-d8b49b74b-hh86q",{"micros":36931,"calls":["get_user",{"micros":8185},"get_guilds",{"micros":5089},"send_scheduled_deletion_message",{"micros":11},"guild_join_requests",{"micros":1},"authorized_ip_coro",{"micros":10}]}]},"starting_guild_connect",{"micros":44,"calls":[]},"presence_started",{"micros":204,"calls":[]},"guilds_started",{"micros":81,"calls":[]},"guilds_connect",{"micros":2,"calls":[]},"presence_connect",{"micros":13169,"calls":[]},"connect_finished",{"micros":13174,"calls":[]},"build_ready",{"micros":16,"calls":[]},"clean_ready",{"micros":0,"calls":[]},"optimize_ready",{"micros":19,"calls":[]},"split_ready",{"micros":0,"calls":[]}]}]}] (Session ID: c4fea8b849dabb4f9ff12ff3868f7ffb).
2023-04-20T13:57:46 [     737] INFO    : client          @run              #709  : Received signal to terminate bot and event loop.
2023-04-20T13:57:46 [     738] INFO    : client          @run              #712  : Cleaning up tasks.
2023-04-20T13:57:46 [     738] INFO    : client          @_cancel_tasks    #86   : Cleaning up after 1 tasks.
2023-04-20T13:57:46 [     861] INFO    : client          @_cancel_tasks    #91   : All tasks finished cancelling.
2023-04-20T13:57:46 [     861] INFO    : client          @_cleanup_loop    #111  : Closing the event loop.
2023-04-20T13:58:05 [     673] WARNING : client          @__init__         #252  : PyNaCl is not installed, voice will NOT be supported
2023-04-20T13:58:05 [     717] INFO    : client          @login            #512  : logging in using static token
2023-04-20T13:58:06 [     425] INFO    : gateway         @identify         #430  : Shard ID None has sent the IDENTIFY payload.
2023-04-20T13:58:06 [     649] INFO    : gateway         @received_message #524  : Shard ID None has connected to Gateway: ["gateway-prd-us-east1-b-14zm",{"micros":110345,"calls":["id_created",{"micros":3610,"calls":[]},"session_lookup_time",{"micros":280,"calls":[]},"session_lookup_finished",{"micros":13,"calls":[]},"discord-sessions-prd-2-82",{"micros":102480,"calls":["start_session",{"micros":65482,"calls":["discord-api-d8b49b74b-wwzfk",{"micros":58198,"calls":["get_user",{"micros":33366},"get_guilds",{"micros":3804},"send_scheduled_deletion_message",{"micros":11},"guild_join_requests",{"micros":140},"authorized_ip_coro",{"micros":14}]}]},"starting_guild_connect",{"micros":45,"calls":[]},"presence_started",{"micros":233,"calls":[]},"guilds_started",{"micros":82,"calls":[]},"guilds_connect",{"micros":2,"calls":[]},"presence_connect",{"micros":36562,"calls":[]},"connect_finished",{"micros":36568,"calls":[]},"build_ready",{"micros":21,"calls":[]},"clean_ready",{"micros":1,"calls":[]},"optimize_ready",{"micros":46,"calls":[]},"split_ready",{"micros":0,"calls":[]}]}]}] (Session ID: 23a62cd82ea2317a1802910b16ad2f3b).
2023-04-20T13:58:21 [     837] INFO    : client          @run              #709  : Received signal to terminate bot and event loop.
2023-04-20T13:58:21 [     838] INFO    : client          @run              #712  : Cleaning up tasks.
2023-04-20T13:58:21 [     839] INFO    : client          @_cancel_tasks    #86   : Cleaning up after 1 tasks.
2023-04-20T13:58:21 [     955] INFO    : client          @_cancel_tasks    #91   : All tasks finished cancelling.
2023-04-20T13:58:21 [     957] INFO    : client          @_cleanup_loop    #111  : Closing the event loop.
2023-04-20T13:58:24 [     581] WARNING : client          @__init__         #252  : PyNaCl is not installed, voice will NOT be supported
2023-04-20T13:58:24 [     634] INFO    : client          @login            #512  : logging in using static token
2023-04-20T13:58:25 [     255] INFO    : gateway         @identify         #430  : Shard ID None has sent the IDENTIFY payload.
2023-04-20T13:58:25 [     510] INFO    : gateway         @received_message #524  : Shard ID None has connected to Gateway: ["gateway-prd-us-east1-b-xkhh",{"micros":140639,"calls":["id_created",{"micros":995,"calls":[]},"session_lookup_time",{"micros":4715,"calls":[]},"session_lookup_finished",{"micros":17,"calls":[]},"discord-sessions-prd-2-52",{"micros":134268,"calls":["start_session",{"micros":118669,"calls":["discord-api-d8b49b74b-5x8sh",{"micros":108450,"calls":["get_user",{"micros":24990},"get_guilds",{"micros":28931},"send_scheduled_deletion_message",{"micros":14},"guild_join_requests",{"micros":2},"authorized_ip_coro",{"micros":15}]}]},"starting_guild_connect",{"micros":41,"calls":[]},"presence_started",{"micros":175,"calls":[]},"guilds_started",{"micros":63,"calls":[]},"guilds_connect",{"micros":1,"calls":[]},"presence_connect",{"micros":15277,"calls":[]},"connect_finished",{"micros":15281,"calls":[]},"build_ready",{"micros":18,"calls":[]},"clean_ready",{"micros":1,"calls":[]},"optimize_ready",{"micros":18,"calls":[]},"split_ready",{"micros":1,"calls":[]}]}]}] (Session ID: 4c1c2573add6a9f74c551a1896bd8135).
2023-04-20T13:59:43 [     372] INFO    : client          @run              #709  : Received signal to terminate bot and event loop.
2023-04-20T13:59:43 [     373] INFO    : client          @run              #712  : Cleaning up tasks.
2023-04-20T13:59:43 [     373] INFO    : client          @_cancel_tasks    #86   : Cleaning up after 1 tasks.
2023-04-20T13:59:43 [     492] INFO    : client          @_cancel_tasks    #91   : All tasks finished cancelling.
2023-04-20T13:59:43 [     493] INFO    : client          @_cleanup_loop    #111  : Closing the event loop.
2023-04-20T14:04:43 [     269] WARNING : client          @__init__         #252  : PyNaCl is not installed, voice will NOT be supported
2023-04-20T14:04:43 [     305] INFO    : client          @login            #512  : logging in using static token
2023-04-20T14:04:44 [      48] INFO    : gateway         @identify         #430  : Shard ID None has sent the IDENTIFY payload.
2023-04-20T14:04:44 [     446] INFO    : gateway         @received_message #524  : Shard ID None has connected to Gateway: ["gateway-prd-us-east1-b-wrs2",{"micros":189252,"calls":["id_created",{"micros":2568,"calls":[]},"session_lookup_time",{"micros":525,"calls":[]},"session_lookup_finished",{"micros":13,"calls":[]},"discord-sessions-prd-2-268",{"micros":185003,"calls":["start_session",{"micros":140920,"calls":["discord-api-d8b49b74b-8dhm5",{"micros":123541,"calls":["get_user",{"micros":23946},"get_guilds",{"micros":29196},"send_scheduled_deletion_message",{"micros":14},"guild_join_requests",{"micros":2},"authorized_ip_coro",{"micros":15}]}]},"starting_guild_connect",{"micros":62,"calls":[]},"presence_started",{"micros":255,"calls":[]},"guilds_started",{"micros":65,"calls":[]},"guilds_connect",{"micros":1,"calls":[]},"presence_connect",{"micros":43655,"calls":[]},"connect_finished",{"micros":43660,"calls":[]},"build_ready",{"micros":20,"calls":[]},"clean_ready",{"micros":0,"calls":[]},"optimize_ready",{"micros":19,"calls":[]},"split_ready",{"micros":1,"calls":[]}]}]}] (Session ID: 5a37336cc227f4c4cbe983900fe09a0d).
2023-04-20T16:44:57 [     646] INFO    : gateway         @poll_event       #615  : Timed out receiving packet. Attempting a reconnect.
2023-04-20T16:44:57 [     646] INFO    : client          @connect          #555  : Got a request to RESUME the websocket.
2023-04-20T16:44:57 [     654] ERROR   : client          @connect          #605  : Attempting a reconnect in 0.23s
Traceback (most recent call last):
  File "C:\Users\aaaa\AppData\Local\Programs\Python\Python310\lib\site-packages\aiohttp\connector.py", line 1152, in _create_direct_connection
    hosts = await asyncio.shield(host_resolved)
  File "C:\Users\aaaa\AppData\Local\Programs\Python\Python310\lib\site-packages\aiohttp\connector.py", line 874, in _resolve_host
    addrs = await self._resolver.resolve(host, port, family=self._family)
  File "C:\Users\aaaa\AppData\Local\Programs\Python\Python310\lib\site-packages\aiohttp\resolver.py", line 33, in resolve
    infos = await self._loop.getaddrinfo(
  File "C:\Users\aaaa\AppData\Local\Programs\Python\Python310\lib\asyncio\base_events.py", line 863, in getaddrinfo
    return await self.run_in_executor(
  File "C:\Users\aaaa\AppData\Local\Programs\Python\Python310\lib\concurrent\futures\thread.py", line 58, in run
    result = self.fn(*self.args, **self.kwargs)
  File "C:\Users\aaaa\AppData\Local\Programs\Python\Python310\lib\socket.py", line 955, in getaddrinfo
    for res in _socket.getaddrinfo(host, port, family, type, proto, flags):
socket.gaierror: [Errno 11004] getaddrinfo failed

The above exception was the direct cause of the following exception:

Traceback (most recent call last):
  File "C:\Users\aaaa\AppData\Local\Programs\Python\Python310\lib\site-packages\discord\client.py", line 550, in connect
    self.ws = await asyncio.wait_for(coro, timeout=60.0)
  File "C:\Users\aaaa\AppData\Local\Programs\Python\Python310\lib\asyncio\tasks.py", line 445, in wait_for
    return fut.result()
  File "C:\Users\aaaa\AppData\Local\Programs\Python\Python310\lib\site-packages\discord\gateway.py", line 330, in from_client
    gateway = gateway or await client.http.get_gateway()
  File "C:\Users\aaaa\AppData\Local\Programs\Python\Python310\lib\site-packages\discord\http.py", line 2821, in get_gateway
    data = await self.request(Route("GET", "/gateway"))
  File "C:\Users\aaaa\AppData\Local\Programs\Python\Python310\lib\site-packages\discord\http.py", line 280, in request
    async with self.__session.request(
  File "C:\Users\aaaa\AppData\Local\Programs\Python\Python310\lib\site-packages\aiohttp\client.py", line 1141, in __aenter__
    self._resp = await self._coro
  File "C:\Users\aaaa\AppData\Local\Programs\Python\Python310\lib\site-packages\aiohttp\client.py", line 536, in _request
    conn = await self._connector.connect(
  File "C:\Users\aaaa\AppData\Local\Programs\Python\Python310\lib\site-packages\aiohttp\connector.py", line 540, in connect
    proto = await self._create_connection(req, traces, timeout)
  File "C:\Users\aaaa\AppData\Local\Programs\Python\Python310\lib\site-packages\aiohttp\connector.py", line 901, in _create_connection
    _, proto = await self._create_direct_connection(req, traces, timeout)
  File "C:\Users\aaaa\AppData\Local\Programs\Python\Python310\lib\site-packages\aiohttp\connector.py", line 1166, in _create_direct_connection
    raise ClientConnectorError(req.connection_key, exc) from exc
aiohttp.client_exceptions.ClientConnectorError: Cannot connect to host discord.com:443 ssl:default [getaddrinfo failed]
2023-04-20T16:44:58 [     335] ERROR   : client          @connect          #605  : Attempting a reconnect in 0.62s
Traceback (most recent call last):
  File "C:\Users\aaaa\AppData\Local\Programs\Python\Python310\lib\site-packages\aiohttp\connector.py", line 1152, in _create_direct_connection
    hosts = await asyncio.shield(host_resolved)
  File "C:\Users\aaaa\AppData\Local\Programs\Python\Python310\lib\site-packages\aiohttp\connector.py", line 874, in _resolve_host
    addrs = await self._resolver.resolve(host, port, family=self._family)
  File "C:\Users\aaaa\AppData\Local\Programs\Python\Python310\lib\site-packages\aiohttp\resolver.py", line 33, in resolve
    infos = await self._loop.getaddrinfo(
  File "C:\Users\aaaa\AppData\Local\Programs\Python\Python310\lib\asyncio\base_events.py", line 863, in getaddrinfo
    return await self.run_in_executor(
  File "C:\Users\aaaa\AppData\Local\Programs\Python\Python310\lib\concurrent\futures\thread.py", line 58, in run
    result = self.fn(*self.args, **self.kwargs)
  File "C:\Users\aaaa\AppData\Local\Programs\Python\Python310\lib\socket.py", line 955, in getaddrinfo
    for res in _socket.getaddrinfo(host, port, family, type, proto, flags):
socket.gaierror: [Errno 11004] getaddrinfo failed

The above exception was the direct cause of the following exception:

Traceback (most recent call last):
  File "C:\Users\aaaa\AppData\Local\Programs\Python\Python310\lib\site-packages\discord\client.py", line 550, in connect
    self.ws = await asyncio.wait_for(coro, timeout=60.0)
  File "C:\Users\aaaa\AppData\Local\Programs\Python\Python310\lib\asyncio\tasks.py", line 445, in wait_for
    return fut.result()
  File "C:\Users\aaaa\AppData\Local\Programs\Python\Python310\lib\site-packages\discord\gateway.py", line 330, in from_client
    gateway = gateway or await client.http.get_gateway()
  File "C:\Users\aaaa\AppData\Local\Programs\Python\Python310\lib\site-packages\discord\http.py", line 2821, in get_gateway
    data = await self.request(Route("GET", "/gateway"))
  File "C:\Users\aaaa\AppData\Local\Programs\Python\Python310\lib\site-packages\discord\http.py", line 280, in request
    async with self.__session.request(
  File "C:\Users\aaaa\AppData\Local\Programs\Python\Python310\lib\site-packages\aiohttp\client.py", line 1141, in __aenter__
    self._resp = await self._coro
  File "C:\Users\aaaa\AppData\Local\Programs\Python\Python310\lib\site-packages\aiohttp\client.py", line 536, in _request
    conn = await self._connector.connect(
  File "C:\Users\aaaa\AppData\Local\Programs\Python\Python310\lib\site-packages\aiohttp\connector.py", line 540, in connect
    proto = await self._create_connection(req, traces, timeout)
  File "C:\Users\aaaa\AppData\Local\Programs\Python\Python310\lib\site-packages\aiohttp\connector.py", line 901, in _create_connection
    _, proto = await self._create_direct_connection(req, traces, timeout)
  File "C:\Users\aaaa\AppData\Local\Programs\Python\Python310\lib\site-packages\aiohttp\connector.py", line 1166, in _create_direct_connection
    raise ClientConnectorError(req.connection_key, exc) from exc
aiohttp.client_exceptions.ClientConnectorError: Cannot connect to host discord.com:443 ssl:default [getaddrinfo failed]
2023-04-20T16:44:59 [      39] ERROR   : client          @connect          #605  : Attempting a reconnect in 2.71s
Traceback (most recent call last):
  File "C:\Users\aaaa\AppData\Local\Programs\Python\Python310\lib\site-packages\aiohttp\connector.py", line 1152, in _create_direct_connection
    hosts = await asyncio.shield(host_resolved)
  File "C:\Users\aaaa\AppData\Local\Programs\Python\Python310\lib\site-packages\aiohttp\connector.py", line 874, in _resolve_host
    addrs = await self._resolver.resolve(host, port, family=self._family)
  File "C:\Users\aaaa\AppData\Local\Programs\Python\Python310\lib\site-packages\aiohttp\resolver.py", line 33, in resolve
    infos = await self._loop.getaddrinfo(
  File "C:\Users\aaaa\AppData\Local\Programs\Python\Python310\lib\asyncio\base_events.py", line 863, in getaddrinfo
    return await self.run_in_executor(
  File "C:\Users\aaaa\AppData\Local\Programs\Python\Python310\lib\concurrent\futures\thread.py", line 58, in run
    result = self.fn(*self.args, **self.kwargs)
  File "C:\Users\aaaa\AppData\Local\Programs\Python\Python310\lib\socket.py", line 955, in getaddrinfo
    for res in _socket.getaddrinfo(host, port, family, type, proto, flags):
socket.gaierror: [Errno 11004] getaddrinfo failed

The above exception was the direct cause of the following exception:

Traceback (most recent call last):
  File "C:\Users\aaaa\AppData\Local\Programs\Python\Python310\lib\site-packages\discord\client.py", line 550, in connect
    self.ws = await asyncio.wait_for(coro, timeout=60.0)
  File "C:\Users\aaaa\AppData\Local\Programs\Python\Python310\lib\asyncio\tasks.py", line 445, in wait_for
    return fut.result()
  File "C:\Users\aaaa\AppData\Local\Programs\Python\Python310\lib\site-packages\discord\gateway.py", line 330, in from_client
    gateway = gateway or await client.http.get_gateway()
  File "C:\Users\aaaa\AppData\Local\Programs\Python\Python310\lib\site-packages\discord\http.py", line 2821, in get_gateway
    data = await self.request(Route("GET", "/gateway"))
  File "C:\Users\aaaa\AppData\Local\Programs\Python\Python310\lib\site-packages\discord\http.py", line 280, in request
    async with self.__session.request(
  File "C:\Users\aaaa\AppData\Local\Programs\Python\Python310\lib\site-packages\aiohttp\client.py", line 1141, in __aenter__
    self._resp = await self._coro
  File "C:\Users\aaaa\AppData\Local\Programs\Python\Python310\lib\site-packages\aiohttp\client.py", line 536, in _request
    conn = await self._connector.connect(
  File "C:\Users\aaaa\AppData\Local\Programs\Python\Python310\lib\site-packages\aiohttp\connector.py", line 540, in connect
    proto = await self._create_connection(req, traces, timeout)
  File "C:\Users\aaaa\AppData\Local\Programs\Python\Python310\lib\site-packages\aiohttp\connector.py", line 901, in _create_connection
    _, proto = await self._create_direct_connection(req, traces, timeout)
  File "C:\Users\aaaa\AppData\Local\Programs\Python\Python310\lib\site-packages\aiohttp\connector.py", line 1166, in _create_direct_connection
    raise ClientConnectorError(req.connection_key, exc) from exc
aiohttp.client_exceptions.ClientConnectorError: Cannot connect to host discord.com:443 ssl:default [getaddrinfo failed]
2023-04-20T16:45:01 [     785] ERROR   : client          @connect          #605  : Attempting a reconnect in 5.07s
Traceback (most recent call last):
  File "C:\Users\aaaa\AppData\Local\Programs\Python\Python310\lib\site-packages\aiohttp\connector.py", line 1152, in _create_direct_connection
    hosts = await asyncio.shield(host_resolved)
  File "C:\Users\aaaa\AppData\Local\Programs\Python\Python310\lib\site-packages\aiohttp\connector.py", line 874, in _resolve_host
    addrs = await self._resolver.resolve(host, port, family=self._family)
  File "C:\Users\aaaa\AppData\Local\Programs\Python\Python310\lib\site-packages\aiohttp\resolver.py", line 33, in resolve
    infos = await self._loop.getaddrinfo(
  File "C:\Users\aaaa\AppData\Local\Programs\Python\Python310\lib\asyncio\base_events.py", line 863, in getaddrinfo
    return await self.run_in_executor(
  File "C:\Users\aaaa\AppData\Local\Programs\Python\Python310\lib\concurrent\futures\thread.py", line 58, in run
    result = self.fn(*self.args, **self.kwargs)
  File "C:\Users\aaaa\AppData\Local\Programs\Python\Python310\lib\socket.py", line 955, in getaddrinfo
    for res in _socket.getaddrinfo(host, port, family, type, proto, flags):
socket.gaierror: [Errno 11004] getaddrinfo failed

The above exception was the direct cause of the following exception:

Traceback (most recent call last):
  File "C:\Users\aaaa\AppData\Local\Programs\Python\Python310\lib\site-packages\discord\client.py", line 550, in connect
    self.ws = await asyncio.wait_for(coro, timeout=60.0)
  File "C:\Users\aaaa\AppData\Local\Programs\Python\Python310\lib\asyncio\tasks.py", line 445, in wait_for
    return fut.result()
  File "C:\Users\aaaa\AppData\Local\Programs\Python\Python310\lib\site-packages\discord\gateway.py", line 330, in from_client
    gateway = gateway or await client.http.get_gateway()
  File "C:\Users\aaaa\AppData\Local\Programs\Python\Python310\lib\site-packages\discord\http.py", line 2821, in get_gateway
    data = await self.request(Route("GET", "/gateway"))
  File "C:\Users\aaaa\AppData\Local\Programs\Python\Python310\lib\site-packages\discord\http.py", line 280, in request
    async with self.__session.request(
  File "C:\Users\aaaa\AppData\Local\Programs\Python\Python310\lib\site-packages\aiohttp\client.py", line 1141, in __aenter__
    self._resp = await self._coro
  File "C:\Users\aaaa\AppData\Local\Programs\Python\Python310\lib\site-packages\aiohttp\client.py", line 536, in _request
    conn = await self._connector.connect(
  File "C:\Users\aaaa\AppData\Local\Programs\Python\Python310\lib\site-packages\aiohttp\connector.py", line 540, in connect
    proto = await self._create_connection(req, traces, timeout)
  File "C:\Users\aaaa\AppData\Local\Programs\Python\Python310\lib\site-packages\aiohttp\connector.py", line 901, in _create_connection
    _, proto = await self._create_direct_connection(req, traces, timeout)
  File "C:\Users\aaaa\AppData\Local\Programs\Python\Python310\lib\site-packages\aiohttp\connector.py", line 1166, in _create_direct_connection
    raise ClientConnectorError(req.connection_key, exc) from exc
aiohttp.client_exceptions.ClientConnectorError: Cannot connect to host discord.com:443 ssl:default [getaddrinfo failed]
2023-04-20T16:45:06 [     876] ERROR   : client          @connect          #605  : Attempting a reconnect in 4.41s
Traceback (most recent call last):
  File "C:\Users\aaaa\AppData\Local\Programs\Python\Python310\lib\site-packages\aiohttp\connector.py", line 1152, in _create_direct_connection
    hosts = await asyncio.shield(host_resolved)
  File "C:\Users\aaaa\AppData\Local\Programs\Python\Python310\lib\site-packages\aiohttp\connector.py", line 874, in _resolve_host
    addrs = await self._resolver.resolve(host, port, family=self._family)
  File "C:\Users\aaaa\AppData\Local\Programs\Python\Python310\lib\site-packages\aiohttp\resolver.py", line 33, in resolve
    infos = await self._loop.getaddrinfo(
  File "C:\Users\aaaa\AppData\Local\Programs\Python\Python310\lib\asyncio\base_events.py", line 863, in getaddrinfo
    return await self.run_in_executor(
  File "C:\Users\aaaa\AppData\Local\Programs\Python\Python310\lib\concurrent\futures\thread.py", line 58, in run
    result = self.fn(*self.args, **self.kwargs)
  File "C:\Users\aaaa\AppData\Local\Programs\Python\Python310\lib\socket.py", line 955, in getaddrinfo
    for res in _socket.getaddrinfo(host, port, family, type, proto, flags):
socket.gaierror: [Errno 11004] getaddrinfo failed

The above exception was the direct cause of the following exception:

Traceback (most recent call last):
  File "C:\Users\aaaa\AppData\Local\Programs\Python\Python310\lib\site-packages\discord\client.py", line 550, in connect
    self.ws = await asyncio.wait_for(coro, timeout=60.0)
  File "C:\Users\aaaa\AppData\Local\Programs\Python\Python310\lib\asyncio\tasks.py", line 445, in wait_for
    return fut.result()
  File "C:\Users\aaaa\AppData\Local\Programs\Python\Python310\lib\site-packages\discord\gateway.py", line 330, in from_client
    gateway = gateway or await client.http.get_gateway()
  File "C:\Users\aaaa\AppData\Local\Programs\Python\Python310\lib\site-packages\discord\http.py", line 2821, in get_gateway
    data = await self.request(Route("GET", "/gateway"))
  File "C:\Users\aaaa\AppData\Local\Programs\Python\Python310\lib\site-packages\discord\http.py", line 280, in request
    async with self.__session.request(
  File "C:\Users\aaaa\AppData\Local\Programs\Python\Python310\lib\site-packages\aiohttp\client.py", line 1141, in __aenter__
    self._resp = await self._coro
  File "C:\Users\aaaa\AppData\Local\Programs\Python\Python310\lib\site-packages\aiohttp\client.py", line 536, in _request
    conn = await self._connector.connect(
  File "C:\Users\aaaa\AppData\Local\Programs\Python\Python310\lib\site-packages\aiohttp\connector.py", line 540, in connect
    proto = await self._create_connection(req, traces, timeout)
  File "C:\Users\aaaa\AppData\Local\Programs\Python\Python310\lib\site-packages\aiohttp\connector.py", line 901, in _create_connection
    _, proto = await self._create_direct_connection(req, traces, timeout)
  File "C:\Users\aaaa\AppData\Local\Programs\Python\Python310\lib\site-packages\aiohttp\connector.py", line 1166, in _create_direct_connection
    raise ClientConnectorError(req.connection_key, exc) from exc
aiohttp.client_exceptions.ClientConnectorError: Cannot connect to host discord.com:443 ssl:default [getaddrinfo failed]
2023-04-20T16:45:11 [     300] ERROR   : client          @connect          #605  : Attempting a reconnect in 52.69s
Traceback (most recent call last):
  File "C:\Users\aaaa\AppData\Local\Programs\Python\Python310\lib\site-packages\aiohttp\connector.py", line 1152, in _create_direct_connection
    hosts = await asyncio.shield(host_resolved)
  File "C:\Users\aaaa\AppData\Local\Programs\Python\Python310\lib\site-packages\aiohttp\connector.py", line 874, in _resolve_host
    addrs = await self._resolver.resolve(host, port, family=self._family)
  File "C:\Users\aaaa\AppData\Local\Programs\Python\Python310\lib\site-packages\aiohttp\resolver.py", line 33, in resolve
    infos = await self._loop.getaddrinfo(
  File "C:\Users\aaaa\AppData\Local\Programs\Python\Python310\lib\asyncio\base_events.py", line 863, in getaddrinfo
    return await self.run_in_executor(
  File "C:\Users\aaaa\AppData\Local\Programs\Python\Python310\lib\concurrent\futures\thread.py", line 58, in run
    result = self.fn(*self.args, **self.kwargs)
  File "C:\Users\aaaa\AppData\Local\Programs\Python\Python310\lib\socket.py", line 955, in getaddrinfo
    for res in _socket.getaddrinfo(host, port, family, type, proto, flags):
socket.gaierror: [Errno 11004] getaddrinfo failed

The above exception was the direct cause of the following exception:

Traceback (most recent call last):
  File "C:\Users\aaaa\AppData\Local\Programs\Python\Python310\lib\site-packages\discord\client.py", line 550, in connect
    self.ws = await asyncio.wait_for(coro, timeout=60.0)
  File "C:\Users\aaaa\AppData\Local\Programs\Python\Python310\lib\asyncio\tasks.py", line 445, in wait_for
    return fut.result()
  File "C:\Users\aaaa\AppData\Local\Programs\Python\Python310\lib\site-packages\discord\gateway.py", line 330, in from_client
    gateway = gateway or await client.http.get_gateway()
  File "C:\Users\aaaa\AppData\Local\Programs\Python\Python310\lib\site-packages\discord\http.py", line 2821, in get_gateway
    data = await self.request(Route("GET", "/gateway"))
  File "C:\Users\aaaa\AppData\Local\Programs\Python\Python310\lib\site-packages\discord\http.py", line 280, in request
    async with self.__session.request(
  File "C:\Users\aaaa\AppData\Local\Programs\Python\Python310\lib\site-packages\aiohttp\client.py", line 1141, in __aenter__
    self._resp = await self._coro
  File "C:\Users\aaaa\AppData\Local\Programs\Python\Python310\lib\site-packages\aiohttp\client.py", line 536, in _request
    conn = await self._connector.connect(
  File "C:\Users\aaaa\AppData\Local\Programs\Python\Python310\lib\site-packages\aiohttp\connector.py", line 540, in connect
    proto = await self._create_connection(req, traces, timeout)
  File "C:\Users\aaaa\AppData\Local\Programs\Python\Python310\lib\site-packages\aiohttp\connector.py", line 901, in _create_connection
    _, proto = await self._create_direct_connection(req, traces, timeout)
  File "C:\Users\aaaa\AppData\Local\Programs\Python\Python310\lib\site-packages\aiohttp\connector.py", line 1166, in _create_direct_connection
    raise ClientConnectorError(req.connection_key, exc) from exc
aiohttp.client_exceptions.ClientConnectorError: Cannot connect to host discord.com:443 ssl:default [getaddrinfo failed]
2023-04-20T16:46:04 [     313] INFO    : gateway         @resume           #444  : Shard ID None has sent the RESUME payload.
2023-04-20T16:46:04 [     448] INFO    : gateway         @received_message #510  : Shard ID None session has been invalidated.
2023-04-20T16:46:04 [     577] INFO    : client          @connect          #555  : Got a request to IDENTIFY the websocket.
2023-04-20T16:46:09 [     790] INFO    : gateway         @identify         #430  : Shard ID None has sent the IDENTIFY payload.
2023-04-20T16:46:10 [     139] INFO    : gateway         @received_message #524  : Shard ID None has connected to Gateway: ["gateway-prd-us-east1-c-6dwh",{"micros":129159,"calls":["id_created",{"micros":1007,"calls":[]},"session_lookup_time",{"micros":281,"calls":[]},"session_lookup_finished",{"micros":14,"calls":[]},"discord-sessions-prd-2-167",{"micros":126793,"calls":["start_session",{"micros":85002,"calls":["discord-api-756ff44b84-5ll7h",{"micros":76094,"calls":["get_user",{"micros":18472},"get_guilds",{"micros":19114},"send_scheduled_deletion_message",{"micros":13},"guild_join_requests",{"micros":3},"authorized_ip_coro",{"micros":15}]}]},"starting_guild_connect",{"micros":47,"calls":[]},"presence_started",{"micros":25094,"calls":[]},"guilds_started",{"micros":105,"calls":[]},"guilds_connect",{"micros":2,"calls":[]},"presence_connect",{"micros":16497,"calls":[]},"connect_finished",{"micros":16503,"calls":[]},"build_ready",{"micros":18,"calls":[]},"clean_ready",{"micros":1,"calls":[]},"optimize_ready",{"micros":20,"calls":[]},"split_ready",{"micros":1,"calls":[]}]}]}] (Session ID: c536222fac96a2d76fbe793fa23bd85e).
2023-04-20T23:02:36 [     492] WARNING : gateway         @run              #141  : Shard ID None has stopped responding to the gateway. Closing and restarting.
2023-04-20T23:02:36 [     495] INFO    : gateway         @poll_event       #615  : Timed out receiving packet. Attempting a reconnect.
2023-04-20T23:02:36 [     495] INFO    : client          @connect          #555  : Got a request to RESUME the websocket.
2023-04-20T23:02:36 [     502] ERROR   : client          @connect          #605  : Attempting a reconnect in 0.42s
Traceback (most recent call last):
  File "C:\Users\aaaa\AppData\Local\Programs\Python\Python310\lib\site-packages\aiohttp\connector.py", line 1152, in _create_direct_connection
    hosts = await asyncio.shield(host_resolved)
  File "C:\Users\aaaa\AppData\Local\Programs\Python\Python310\lib\site-packages\aiohttp\connector.py", line 874, in _resolve_host
    addrs = await self._resolver.resolve(host, port, family=self._family)
  File "C:\Users\aaaa\AppData\Local\Programs\Python\Python310\lib\site-packages\aiohttp\resolver.py", line 33, in resolve
    infos = await self._loop.getaddrinfo(
  File "C:\Users\aaaa\AppData\Local\Programs\Python\Python310\lib\asyncio\base_events.py", line 863, in getaddrinfo
    return await self.run_in_executor(
  File "C:\Users\aaaa\AppData\Local\Programs\Python\Python310\lib\concurrent\futures\thread.py", line 58, in run
    result = self.fn(*self.args, **self.kwargs)
  File "C:\Users\aaaa\AppData\Local\Programs\Python\Python310\lib\socket.py", line 955, in getaddrinfo
    for res in _socket.getaddrinfo(host, port, family, type, proto, flags):
socket.gaierror: [Errno 11004] getaddrinfo failed

The above exception was the direct cause of the following exception:

Traceback (most recent call last):
  File "C:\Users\aaaa\AppData\Local\Programs\Python\Python310\lib\site-packages\discord\client.py", line 550, in connect
    self.ws = await asyncio.wait_for(coro, timeout=60.0)
  File "C:\Users\aaaa\AppData\Local\Programs\Python\Python310\lib\asyncio\tasks.py", line 445, in wait_for
    return fut.result()
  File "C:\Users\aaaa\AppData\Local\Programs\Python\Python310\lib\site-packages\discord\gateway.py", line 330, in from_client
    gateway = gateway or await client.http.get_gateway()
  File "C:\Users\aaaa\AppData\Local\Programs\Python\Python310\lib\site-packages\discord\http.py", line 2821, in get_gateway
    data = await self.request(Route("GET", "/gateway"))
  File "C:\Users\aaaa\AppData\Local\Programs\Python\Python310\lib\site-packages\discord\http.py", line 280, in request
    async with self.__session.request(
  File "C:\Users\aaaa\AppData\Local\Programs\Python\Python310\lib\site-packages\aiohttp\client.py", line 1141, in __aenter__
    self._resp = await self._coro
  File "C:\Users\aaaa\AppData\Local\Programs\Python\Python310\lib\site-packages\aiohttp\client.py", line 536, in _request
    conn = await self._connector.connect(
  File "C:\Users\aaaa\AppData\Local\Programs\Python\Python310\lib\site-packages\aiohttp\connector.py", line 540, in connect
    proto = await self._create_connection(req, traces, timeout)
  File "C:\Users\aaaa\AppData\Local\Programs\Python\Python310\lib\site-packages\aiohttp\connector.py", line 901, in _create_connection
    _, proto = await self._create_direct_connection(req, traces, timeout)
  File "C:\Users\aaaa\AppData\Local\Programs\Python\Python310\lib\site-packages\aiohttp\connector.py", line 1166, in _create_direct_connection
    raise ClientConnectorError(req.connection_key, exc) from exc
aiohttp.client_exceptions.ClientConnectorError: Cannot connect to host discord.com:443 ssl:default [getaddrinfo failed]
2023-04-20T23:02:36 [     946] ERROR   : client          @connect          #605  : Attempting a reconnect in 3.16s
Traceback (most recent call last):
  File "C:\Users\aaaa\AppData\Local\Programs\Python\Python310\lib\site-packages\aiohttp\connector.py", line 1152, in _create_direct_connection
    hosts = await asyncio.shield(host_resolved)
  File "C:\Users\aaaa\AppData\Local\Programs\Python\Python310\lib\site-packages\aiohttp\connector.py", line 874, in _resolve_host
    addrs = await self._resolver.resolve(host, port, family=self._family)
  File "C:\Users\aaaa\AppData\Local\Programs\Python\Python310\lib\site-packages\aiohttp\resolver.py", line 33, in resolve
    infos = await self._loop.getaddrinfo(
  File "C:\Users\aaaa\AppData\Local\Programs\Python\Python310\lib\asyncio\base_events.py", line 863, in getaddrinfo
    return await self.run_in_executor(
  File "C:\Users\aaaa\AppData\Local\Programs\Python\Python310\lib\concurrent\futures\thread.py", line 58, in run
    result = self.fn(*self.args, **self.kwargs)
  File "C:\Users\aaaa\AppData\Local\Programs\Python\Python310\lib\socket.py", line 955, in getaddrinfo
    for res in _socket.getaddrinfo(host, port, family, type, proto, flags):
socket.gaierror: [Errno 11004] getaddrinfo failed

The above exception was the direct cause of the following exception:

Traceback (most recent call last):
  File "C:\Users\aaaa\AppData\Local\Programs\Python\Python310\lib\site-packages\discord\client.py", line 550, in connect
    self.ws = await asyncio.wait_for(coro, timeout=60.0)
  File "C:\Users\aaaa\AppData\Local\Programs\Python\Python310\lib\asyncio\tasks.py", line 445, in wait_for
    return fut.result()
  File "C:\Users\aaaa\AppData\Local\Programs\Python\Python310\lib\site-packages\discord\gateway.py", line 330, in from_client
    gateway = gateway or await client.http.get_gateway()
  File "C:\Users\aaaa\AppData\Local\Programs\Python\Python310\lib\site-packages\discord\http.py", line 2821, in get_gateway
    data = await self.request(Route("GET", "/gateway"))
  File "C:\Users\aaaa\AppData\Local\Programs\Python\Python310\lib\site-packages\discord\http.py", line 280, in request
    async with self.__session.request(
  File "C:\Users\aaaa\AppData\Local\Programs\Python\Python310\lib\site-packages\aiohttp\client.py", line 1141, in __aenter__
    self._resp = await self._coro
  File "C:\Users\aaaa\AppData\Local\Programs\Python\Python310\lib\site-packages\aiohttp\client.py", line 536, in _request
    conn = await self._connector.connect(
  File "C:\Users\aaaa\AppData\Local\Programs\Python\Python310\lib\site-packages\aiohttp\connector.py", line 540, in connect
    proto = await self._create_connection(req, traces, timeout)
  File "C:\Users\aaaa\AppData\Local\Programs\Python\Python310\lib\site-packages\aiohttp\connector.py", line 901, in _create_connection
    _, proto = await self._create_direct_connection(req, traces, timeout)
  File "C:\Users\aaaa\AppData\Local\Programs\Python\Python310\lib\site-packages\aiohttp\connector.py", line 1166, in _create_direct_connection
    raise ClientConnectorError(req.connection_key, exc) from exc
aiohttp.client_exceptions.ClientConnectorError: Cannot connect to host discord.com:443 ssl:default [getaddrinfo failed]
2023-04-20T23:02:40 [     129] ERROR   : client          @connect          #605  : Attempting a reconnect in 6.32s
Traceback (most recent call last):
  File "C:\Users\aaaa\AppData\Local\Programs\Python\Python310\lib\site-packages\aiohttp\connector.py", line 1152, in _create_direct_connection
    hosts = await asyncio.shield(host_resolved)
  File "C:\Users\aaaa\AppData\Local\Programs\Python\Python310\lib\site-packages\aiohttp\connector.py", line 874, in _resolve_host
    addrs = await self._resolver.resolve(host, port, family=self._family)
  File "C:\Users\aaaa\AppData\Local\Programs\Python\Python310\lib\site-packages\aiohttp\resolver.py", line 33, in resolve
    infos = await self._loop.getaddrinfo(
  File "C:\Users\aaaa\AppData\Local\Programs\Python\Python310\lib\asyncio\base_events.py", line 863, in getaddrinfo
    return await self.run_in_executor(
  File "C:\Users\aaaa\AppData\Local\Programs\Python\Python310\lib\concurrent\futures\thread.py", line 58, in run
    result = self.fn(*self.args, **self.kwargs)
  File "C:\Users\aaaa\AppData\Local\Programs\Python\Python310\lib\socket.py", line 955, in getaddrinfo
    for res in _socket.getaddrinfo(host, port, family, type, proto, flags):
socket.gaierror: [Errno 11004] getaddrinfo failed

The above exception was the direct cause of the following exception:

Traceback (most recent call last):
  File "C:\Users\aaaa\AppData\Local\Programs\Python\Python310\lib\site-packages\discord\client.py", line 550, in connect
    self.ws = await asyncio.wait_for(coro, timeout=60.0)
  File "C:\Users\aaaa\AppData\Local\Programs\Python\Python310\lib\asyncio\tasks.py", line 445, in wait_for
    return fut.result()
  File "C:\Users\aaaa\AppData\Local\Programs\Python\Python310\lib\site-packages\discord\gateway.py", line 330, in from_client
    gateway = gateway or await client.http.get_gateway()
  File "C:\Users\aaaa\AppData\Local\Programs\Python\Python310\lib\site-packages\discord\http.py", line 2821, in get_gateway
    data = await self.request(Route("GET", "/gateway"))
  File "C:\Users\aaaa\AppData\Local\Programs\Python\Python310\lib\site-packages\discord\http.py", line 280, in request
    async with self.__session.request(
  File "C:\Users\aaaa\AppData\Local\Programs\Python\Python310\lib\site-packages\aiohttp\client.py", line 1141, in __aenter__
    self._resp = await self._coro
  File "C:\Users\aaaa\AppData\Local\Programs\Python\Python310\lib\site-packages\aiohttp\client.py", line 536, in _request
    conn = await self._connector.connect(
  File "C:\Users\aaaa\AppData\Local\Programs\Python\Python310\lib\site-packages\aiohttp\connector.py", line 540, in connect
    proto = await self._create_connection(req, traces, timeout)
  File "C:\Users\aaaa\AppData\Local\Programs\Python\Python310\lib\site-packages\aiohttp\connector.py", line 901, in _create_connection
    _, proto = await self._create_direct_connection(req, traces, timeout)
  File "C:\Users\aaaa\AppData\Local\Programs\Python\Python310\lib\site-packages\aiohttp\connector.py", line 1166, in _create_direct_connection
    raise ClientConnectorError(req.connection_key, exc) from exc
aiohttp.client_exceptions.ClientConnectorError: Cannot connect to host discord.com:443 ssl:default [getaddrinfo failed]
2023-04-20T23:02:46 [     466] ERROR   : client          @connect          #605  : Attempting a reconnect in 9.73s
Traceback (most recent call last):
  File "C:\Users\aaaa\AppData\Local\Programs\Python\Python310\lib\site-packages\aiohttp\connector.py", line 1152, in _create_direct_connection
    hosts = await asyncio.shield(host_resolved)
  File "C:\Users\aaaa\AppData\Local\Programs\Python\Python310\lib\site-packages\aiohttp\connector.py", line 874, in _resolve_host
    addrs = await self._resolver.resolve(host, port, family=self._family)
  File "C:\Users\aaaa\AppData\Local\Programs\Python\Python310\lib\site-packages\aiohttp\resolver.py", line 33, in resolve
    infos = await self._loop.getaddrinfo(
  File "C:\Users\aaaa\AppData\Local\Programs\Python\Python310\lib\asyncio\base_events.py", line 863, in getaddrinfo
    return await self.run_in_executor(
  File "C:\Users\aaaa\AppData\Local\Programs\Python\Python310\lib\concurrent\futures\thread.py", line 58, in run
    result = self.fn(*self.args, **self.kwargs)
  File "C:\Users\aaaa\AppData\Local\Programs\Python\Python310\lib\socket.py", line 955, in getaddrinfo
    for res in _socket.getaddrinfo(host, port, family, type, proto, flags):
socket.gaierror: [Errno 11004] getaddrinfo failed

The above exception was the direct cause of the following exception:

Traceback (most recent call last):
  File "C:\Users\aaaa\AppData\Local\Programs\Python\Python310\lib\site-packages\discord\client.py", line 550, in connect
    self.ws = await asyncio.wait_for(coro, timeout=60.0)
  File "C:\Users\aaaa\AppData\Local\Programs\Python\Python310\lib\asyncio\tasks.py", line 445, in wait_for
    return fut.result()
  File "C:\Users\aaaa\AppData\Local\Programs\Python\Python310\lib\site-packages\discord\gateway.py", line 330, in from_client
    gateway = gateway or await client.http.get_gateway()
  File "C:\Users\aaaa\AppData\Local\Programs\Python\Python310\lib\site-packages\discord\http.py", line 2821, in get_gateway
    data = await self.request(Route("GET", "/gateway"))
  File "C:\Users\aaaa\AppData\Local\Programs\Python\Python310\lib\site-packages\discord\http.py", line 280, in request
    async with self.__session.request(
  File "C:\Users\aaaa\AppData\Local\Programs\Python\Python310\lib\site-packages\aiohttp\client.py", line 1141, in __aenter__
    self._resp = await self._coro
  File "C:\Users\aaaa\AppData\Local\Programs\Python\Python310\lib\site-packages\aiohttp\client.py", line 536, in _request
    conn = await self._connector.connect(
  File "C:\Users\aaaa\AppData\Local\Programs\Python\Python310\lib\site-packages\aiohttp\connector.py", line 540, in connect
    proto = await self._create_connection(req, traces, timeout)
  File "C:\Users\aaaa\AppData\Local\Programs\Python\Python310\lib\site-packages\aiohttp\connector.py", line 901, in _create_connection
    _, proto = await self._create_direct_connection(req, traces, timeout)
  File "C:\Users\aaaa\AppData\Local\Programs\Python\Python310\lib\site-packages\aiohttp\connector.py", line 1166, in _create_direct_connection
    raise ClientConnectorError(req.connection_key, exc) from exc
aiohttp.client_exceptions.ClientConnectorError: Cannot connect to host discord.com:443 ssl:default [getaddrinfo failed]
2023-04-20T23:02:56 [     220] ERROR   : client          @connect          #605  : Attempting a reconnect in 16.76s
Traceback (most recent call last):
  File "C:\Users\aaaa\AppData\Local\Programs\Python\Python310\lib\site-packages\aiohttp\connector.py", line 1152, in _create_direct_connection
    hosts = await asyncio.shield(host_resolved)
  File "C:\Users\aaaa\AppData\Local\Programs\Python\Python310\lib\site-packages\aiohttp\connector.py", line 874, in _resolve_host
    addrs = await self._resolver.resolve(host, port, family=self._family)
  File "C:\Users\aaaa\AppData\Local\Programs\Python\Python310\lib\site-packages\aiohttp\resolver.py", line 33, in resolve
    infos = await self._loop.getaddrinfo(
  File "C:\Users\aaaa\AppData\Local\Programs\Python\Python310\lib\asyncio\base_events.py", line 863, in getaddrinfo
    return await self.run_in_executor(
  File "C:\Users\aaaa\AppData\Local\Programs\Python\Python310\lib\concurrent\futures\thread.py", line 58, in run
    result = self.fn(*self.args, **self.kwargs)
  File "C:\Users\aaaa\AppData\Local\Programs\Python\Python310\lib\socket.py", line 955, in getaddrinfo
    for res in _socket.getaddrinfo(host, port, family, type, proto, flags):
socket.gaierror: [Errno 11004] getaddrinfo failed

The above exception was the direct cause of the following exception:

Traceback (most recent call last):
  File "C:\Users\aaaa\AppData\Local\Programs\Python\Python310\lib\site-packages\discord\client.py", line 550, in connect
    self.ws = await asyncio.wait_for(coro, timeout=60.0)
  File "C:\Users\aaaa\AppData\Local\Programs\Python\Python310\lib\asyncio\tasks.py", line 445, in wait_for
    return fut.result()
  File "C:\Users\aaaa\AppData\Local\Programs\Python\Python310\lib\site-packages\discord\gateway.py", line 330, in from_client
    gateway = gateway or await client.http.get_gateway()
  File "C:\Users\aaaa\AppData\Local\Programs\Python\Python310\lib\site-packages\discord\http.py", line 2821, in get_gateway
    data = await self.request(Route("GET", "/gateway"))
  File "C:\Users\aaaa\AppData\Local\Programs\Python\Python310\lib\site-packages\discord\http.py", line 280, in request
    async with self.__session.request(
  File "C:\Users\aaaa\AppData\Local\Programs\Python\Python310\lib\site-packages\aiohttp\client.py", line 1141, in __aenter__
    self._resp = await self._coro
  File "C:\Users\aaaa\AppData\Local\Programs\Python\Python310\lib\site-packages\aiohttp\client.py", line 536, in _request
    conn = await self._connector.connect(
  File "C:\Users\aaaa\AppData\Local\Programs\Python\Python310\lib\site-packages\aiohttp\connector.py", line 540, in connect
    proto = await self._create_connection(req, traces, timeout)
  File "C:\Users\aaaa\AppData\Local\Programs\Python\Python310\lib\site-packages\aiohttp\connector.py", line 901, in _create_connection
    _, proto = await self._create_direct_connection(req, traces, timeout)
  File "C:\Users\aaaa\AppData\Local\Programs\Python\Python310\lib\site-packages\aiohttp\connector.py", line 1166, in _create_direct_connection
    raise ClientConnectorError(req.connection_key, exc) from exc
aiohttp.client_exceptions.ClientConnectorError: Cannot connect to host discord.com:443 ssl:default [getaddrinfo failed]
2023-04-20T23:03:13 [       6] ERROR   : client          @connect          #605  : Attempting a reconnect in 50.87s
Traceback (most recent call last):
  File "C:\Users\aaaa\AppData\Local\Programs\Python\Python310\lib\site-packages\aiohttp\connector.py", line 1152, in _create_direct_connection
    hosts = await asyncio.shield(host_resolved)
  File "C:\Users\aaaa\AppData\Local\Programs\Python\Python310\lib\site-packages\aiohttp\connector.py", line 874, in _resolve_host
    addrs = await self._resolver.resolve(host, port, family=self._family)
  File "C:\Users\aaaa\AppData\Local\Programs\Python\Python310\lib\site-packages\aiohttp\resolver.py", line 33, in resolve
    infos = await self._loop.getaddrinfo(
  File "C:\Users\aaaa\AppData\Local\Programs\Python\Python310\lib\asyncio\base_events.py", line 863, in getaddrinfo
    return await self.run_in_executor(
  File "C:\Users\aaaa\AppData\Local\Programs\Python\Python310\lib\concurrent\futures\thread.py", line 58, in run
    result = self.fn(*self.args, **self.kwargs)
  File "C:\Users\aaaa\AppData\Local\Programs\Python\Python310\lib\socket.py", line 955, in getaddrinfo
    for res in _socket.getaddrinfo(host, port, family, type, proto, flags):
socket.gaierror: [Errno 11004] getaddrinfo failed

The above exception was the direct cause of the following exception:

Traceback (most recent call last):
  File "C:\Users\aaaa\AppData\Local\Programs\Python\Python310\lib\site-packages\discord\client.py", line 550, in connect
    self.ws = await asyncio.wait_for(coro, timeout=60.0)
  File "C:\Users\aaaa\AppData\Local\Programs\Python\Python310\lib\asyncio\tasks.py", line 445, in wait_for
    return fut.result()
  File "C:\Users\aaaa\AppData\Local\Programs\Python\Python310\lib\site-packages\discord\gateway.py", line 330, in from_client
    gateway = gateway or await client.http.get_gateway()
  File "C:\Users\aaaa\AppData\Local\Programs\Python\Python310\lib\site-packages\discord\http.py", line 2821, in get_gateway
    data = await self.request(Route("GET", "/gateway"))
  File "C:\Users\aaaa\AppData\Local\Programs\Python\Python310\lib\site-packages\discord\http.py", line 280, in request
    async with self.__session.request(
  File "C:\Users\aaaa\AppData\Local\Programs\Python\Python310\lib\site-packages\aiohttp\client.py", line 1141, in __aenter__
    self._resp = await self._coro
  File "C:\Users\aaaa\AppData\Local\Programs\Python\Python310\lib\site-packages\aiohttp\client.py", line 536, in _request
    conn = await self._connector.connect(
  File "C:\Users\aaaa\AppData\Local\Programs\Python\Python310\lib\site-packages\aiohttp\connector.py", line 540, in connect
    proto = await self._create_connection(req, traces, timeout)
  File "C:\Users\aaaa\AppData\Local\Programs\Python\Python310\lib\site-packages\aiohttp\connector.py", line 901, in _create_connection
    _, proto = await self._create_direct_connection(req, traces, timeout)
  File "C:\Users\aaaa\AppData\Local\Programs\Python\Python310\lib\site-packages\aiohttp\connector.py", line 1166, in _create_direct_connection
    raise ClientConnectorError(req.connection_key, exc) from exc
aiohttp.client_exceptions.ClientConnectorError: Cannot connect to host discord.com:443 ssl:default [getaddrinfo failed]
2023-04-20T23:04:03 [     900] ERROR   : client          @connect          #605  : Attempting a reconnect in 84.72s
Traceback (most recent call last):
  File "C:\Users\aaaa\AppData\Local\Programs\Python\Python310\lib\site-packages\aiohttp\connector.py", line 1152, in _create_direct_connection
    hosts = await asyncio.shield(host_resolved)
  File "C:\Users\aaaa\AppData\Local\Programs\Python\Python310\lib\site-packages\aiohttp\connector.py", line 874, in _resolve_host
    addrs = await self._resolver.resolve(host, port, family=self._family)
  File "C:\Users\aaaa\AppData\Local\Programs\Python\Python310\lib\site-packages\aiohttp\resolver.py", line 33, in resolve
    infos = await self._loop.getaddrinfo(
  File "C:\Users\aaaa\AppData\Local\Programs\Python\Python310\lib\asyncio\base_events.py", line 863, in getaddrinfo
    return await self.run_in_executor(
  File "C:\Users\aaaa\AppData\Local\Programs\Python\Python310\lib\concurrent\futures\thread.py", line 58, in run
    result = self.fn(*self.args, **self.kwargs)
  File "C:\Users\aaaa\AppData\Local\Programs\Python\Python310\lib\socket.py", line 955, in getaddrinfo
    for res in _socket.getaddrinfo(host, port, family, type, proto, flags):
socket.gaierror: [Errno 11004] getaddrinfo failed

The above exception was the direct cause of the following exception:

Traceback (most recent call last):
  File "C:\Users\aaaa\AppData\Local\Programs\Python\Python310\lib\site-packages\discord\client.py", line 550, in connect
    self.ws = await asyncio.wait_for(coro, timeout=60.0)
  File "C:\Users\aaaa\AppData\Local\Programs\Python\Python310\lib\asyncio\tasks.py", line 445, in wait_for
    return fut.result()
  File "C:\Users\aaaa\AppData\Local\Programs\Python\Python310\lib\site-packages\discord\gateway.py", line 330, in from_client
    gateway = gateway or await client.http.get_gateway()
  File "C:\Users\aaaa\AppData\Local\Programs\Python\Python310\lib\site-packages\discord\http.py", line 2821, in get_gateway
    data = await self.request(Route("GET", "/gateway"))
  File "C:\Users\aaaa\AppData\Local\Programs\Python\Python310\lib\site-packages\discord\http.py", line 280, in request
    async with self.__session.request(
  File "C:\Users\aaaa\AppData\Local\Programs\Python\Python310\lib\site-packages\aiohttp\client.py", line 1141, in __aenter__
    self._resp = await self._coro
  File "C:\Users\aaaa\AppData\Local\Programs\Python\Python310\lib\site-packages\aiohttp\client.py", line 536, in _request
    conn = await self._connector.connect(
  File "C:\Users\aaaa\AppData\Local\Programs\Python\Python310\lib\site-packages\aiohttp\connector.py", line 540, in connect
    proto = await self._create_connection(req, traces, timeout)
  File "C:\Users\aaaa\AppData\Local\Programs\Python\Python310\lib\site-packages\aiohttp\connector.py", line 901, in _create_connection
    _, proto = await self._create_direct_connection(req, traces, timeout)
  File "C:\Users\aaaa\AppData\Local\Programs\Python\Python310\lib\site-packages\aiohttp\connector.py", line 1166, in _create_direct_connection
    raise ClientConnectorError(req.connection_key, exc) from exc
aiohttp.client_exceptions.ClientConnectorError: Cannot connect to host discord.com:443 ssl:default [getaddrinfo failed]
2023-04-20T23:05:28 [     630] ERROR   : client          @connect          #605  : Attempting a reconnect in 197.11s
Traceback (most recent call last):
  File "C:\Users\aaaa\AppData\Local\Programs\Python\Python310\lib\site-packages\aiohttp\connector.py", line 1152, in _create_direct_connection
    hosts = await asyncio.shield(host_resolved)
  File "C:\Users\aaaa\AppData\Local\Programs\Python\Python310\lib\site-packages\aiohttp\connector.py", line 874, in _resolve_host
    addrs = await self._resolver.resolve(host, port, family=self._family)
  File "C:\Users\aaaa\AppData\Local\Programs\Python\Python310\lib\site-packages\aiohttp\resolver.py", line 33, in resolve
    infos = await self._loop.getaddrinfo(
  File "C:\Users\aaaa\AppData\Local\Programs\Python\Python310\lib\asyncio\base_events.py", line 863, in getaddrinfo
    return await self.run_in_executor(
  File "C:\Users\aaaa\AppData\Local\Programs\Python\Python310\lib\concurrent\futures\thread.py", line 58, in run
    result = self.fn(*self.args, **self.kwargs)
  File "C:\Users\aaaa\AppData\Local\Programs\Python\Python310\lib\socket.py", line 955, in getaddrinfo
    for res in _socket.getaddrinfo(host, port, family, type, proto, flags):
socket.gaierror: [Errno 11004] getaddrinfo failed

The above exception was the direct cause of the following exception:

Traceback (most recent call last):
  File "C:\Users\aaaa\AppData\Local\Programs\Python\Python310\lib\site-packages\discord\client.py", line 550, in connect
    self.ws = await asyncio.wait_for(coro, timeout=60.0)
  File "C:\Users\aaaa\AppData\Local\Programs\Python\Python310\lib\asyncio\tasks.py", line 445, in wait_for
    return fut.result()
  File "C:\Users\aaaa\AppData\Local\Programs\Python\Python310\lib\site-packages\discord\gateway.py", line 330, in from_client
    gateway = gateway or await client.http.get_gateway()
  File "C:\Users\aaaa\AppData\Local\Programs\Python\Python310\lib\site-packages\discord\http.py", line 2821, in get_gateway
    data = await self.request(Route("GET", "/gateway"))
  File "C:\Users\aaaa\AppData\Local\Programs\Python\Python310\lib\site-packages\discord\http.py", line 280, in request
    async with self.__session.request(
  File "C:\Users\aaaa\AppData\Local\Programs\Python\Python310\lib\site-packages\aiohttp\client.py", line 1141, in __aenter__
    self._resp = await self._coro
  File "C:\Users\aaaa\AppData\Local\Programs\Python\Python310\lib\site-packages\aiohttp\client.py", line 536, in _request
    conn = await self._connector.connect(
  File "C:\Users\aaaa\AppData\Local\Programs\Python\Python310\lib\site-packages\aiohttp\connector.py", line 540, in connect
    proto = await self._create_connection(req, traces, timeout)
  File "C:\Users\aaaa\AppData\Local\Programs\Python\Python310\lib\site-packages\aiohttp\connector.py", line 901, in _create_connection
    _, proto = await self._create_direct_connection(req, traces, timeout)
  File "C:\Users\aaaa\AppData\Local\Programs\Python\Python310\lib\site-packages\aiohttp\connector.py", line 1166, in _create_direct_connection
    raise ClientConnectorError(req.connection_key, exc) from exc
aiohttp.client_exceptions.ClientConnectorError: Cannot connect to host discord.com:443 ssl:default [getaddrinfo failed]
2023-04-20T23:08:45 [     764] ERROR   : client          @connect          #605  : Attempting a reconnect in 162.38s
Traceback (most recent call last):
  File "C:\Users\aaaa\AppData\Local\Programs\Python\Python310\lib\site-packages\aiohttp\connector.py", line 1152, in _create_direct_connection
    hosts = await asyncio.shield(host_resolved)
  File "C:\Users\aaaa\AppData\Local\Programs\Python\Python310\lib\site-packages\aiohttp\connector.py", line 874, in _resolve_host
    addrs = await self._resolver.resolve(host, port, family=self._family)
  File "C:\Users\aaaa\AppData\Local\Programs\Python\Python310\lib\site-packages\aiohttp\resolver.py", line 33, in resolve
    infos = await self._loop.getaddrinfo(
  File "C:\Users\aaaa\AppData\Local\Programs\Python\Python310\lib\asyncio\base_events.py", line 863, in getaddrinfo
    return await self.run_in_executor(
  File "C:\Users\aaaa\AppData\Local\Programs\Python\Python310\lib\concurrent\futures\thread.py", line 58, in run
    result = self.fn(*self.args, **self.kwargs)
  File "C:\Users\aaaa\AppData\Local\Programs\Python\Python310\lib\socket.py", line 955, in getaddrinfo
    for res in _socket.getaddrinfo(host, port, family, type, proto, flags):
socket.gaierror: [Errno 11004] getaddrinfo failed

The above exception was the direct cause of the following exception:

Traceback (most recent call last):
  File "C:\Users\aaaa\AppData\Local\Programs\Python\Python310\lib\site-packages\discord\client.py", line 550, in connect
    self.ws = await asyncio.wait_for(coro, timeout=60.0)
  File "C:\Users\aaaa\AppData\Local\Programs\Python\Python310\lib\asyncio\tasks.py", line 445, in wait_for
    return fut.result()
  File "C:\Users\aaaa\AppData\Local\Programs\Python\Python310\lib\site-packages\discord\gateway.py", line 330, in from_client
    gateway = gateway or await client.http.get_gateway()
  File "C:\Users\aaaa\AppData\Local\Programs\Python\Python310\lib\site-packages\discord\http.py", line 2821, in get_gateway
    data = await self.request(Route("GET", "/gateway"))
  File "C:\Users\aaaa\AppData\Local\Programs\Python\Python310\lib\site-packages\discord\http.py", line 280, in request
    async with self.__session.request(
  File "C:\Users\aaaa\AppData\Local\Programs\Python\Python310\lib\site-packages\aiohttp\client.py", line 1141, in __aenter__
    self._resp = await self._coro
  File "C:\Users\aaaa\AppData\Local\Programs\Python\Python310\lib\site-packages\aiohttp\client.py", line 536, in _request
    conn = await self._connector.connect(
  File "C:\Users\aaaa\AppData\Local\Programs\Python\Python310\lib\site-packages\aiohttp\connector.py", line 540, in connect
    proto = await self._create_connection(req, traces, timeout)
  File "C:\Users\aaaa\AppData\Local\Programs\Python\Python310\lib\site-packages\aiohttp\connector.py", line 901, in _create_connection
    _, proto = await self._create_direct_connection(req, traces, timeout)
  File "C:\Users\aaaa\AppData\Local\Programs\Python\Python310\lib\site-packages\aiohttp\connector.py", line 1166, in _create_direct_connection
    raise ClientConnectorError(req.connection_key, exc) from exc
aiohttp.client_exceptions.ClientConnectorError: Cannot connect to host discord.com:443 ssl:default [getaddrinfo failed]
2023-04-20T23:11:28 [     161] ERROR   : client          @connect          #605  : Attempting a reconnect in 164.94s
Traceback (most recent call last):
  File "C:\Users\aaaa\AppData\Local\Programs\Python\Python310\lib\site-packages\aiohttp\connector.py", line 1152, in _create_direct_connection
    hosts = await asyncio.shield(host_resolved)
  File "C:\Users\aaaa\AppData\Local\Programs\Python\Python310\lib\site-packages\aiohttp\connector.py", line 874, in _resolve_host
    addrs = await self._resolver.resolve(host, port, family=self._family)
  File "C:\Users\aaaa\AppData\Local\Programs\Python\Python310\lib\site-packages\aiohttp\resolver.py", line 33, in resolve
    infos = await self._loop.getaddrinfo(
  File "C:\Users\aaaa\AppData\Local\Programs\Python\Python310\lib\asyncio\base_events.py", line 863, in getaddrinfo
    return await self.run_in_executor(
  File "C:\Users\aaaa\AppData\Local\Programs\Python\Python310\lib\concurrent\futures\thread.py", line 58, in run
    result = self.fn(*self.args, **self.kwargs)
  File "C:\Users\aaaa\AppData\Local\Programs\Python\Python310\lib\socket.py", line 955, in getaddrinfo
    for res in _socket.getaddrinfo(host, port, family, type, proto, flags):
socket.gaierror: [Errno 11004] getaddrinfo failed

The above exception was the direct cause of the following exception:

Traceback (most recent call last):
  File "C:\Users\aaaa\AppData\Local\Programs\Python\Python310\lib\site-packages\discord\client.py", line 550, in connect
    self.ws = await asyncio.wait_for(coro, timeout=60.0)
  File "C:\Users\aaaa\AppData\Local\Programs\Python\Python310\lib\asyncio\tasks.py", line 445, in wait_for
    return fut.result()
  File "C:\Users\aaaa\AppData\Local\Programs\Python\Python310\lib\site-packages\discord\gateway.py", line 330, in from_client
    gateway = gateway or await client.http.get_gateway()
  File "C:\Users\aaaa\AppData\Local\Programs\Python\Python310\lib\site-packages\discord\http.py", line 2821, in get_gateway
    data = await self.request(Route("GET", "/gateway"))
  File "C:\Users\aaaa\AppData\Local\Programs\Python\Python310\lib\site-packages\discord\http.py", line 280, in request
    async with self.__session.request(
  File "C:\Users\aaaa\AppData\Local\Programs\Python\Python310\lib\site-packages\aiohttp\client.py", line 1141, in __aenter__
    self._resp = await self._coro
  File "C:\Users\aaaa\AppData\Local\Programs\Python\Python310\lib\site-packages\aiohttp\client.py", line 536, in _request
    conn = await self._connector.connect(
  File "C:\Users\aaaa\AppData\Local\Programs\Python\Python310\lib\site-packages\aiohttp\connector.py", line 540, in connect
    proto = await self._create_connection(req, traces, timeout)
  File "C:\Users\aaaa\AppData\Local\Programs\Python\Python310\lib\site-packages\aiohttp\connector.py", line 901, in _create_connection
    _, proto = await self._create_direct_connection(req, traces, timeout)
  File "C:\Users\aaaa\AppData\Local\Programs\Python\Python310\lib\site-packages\aiohttp\connector.py", line 1166, in _create_direct_connection
    raise ClientConnectorError(req.connection_key, exc) from exc
aiohttp.client_exceptions.ClientConnectorError: Cannot connect to host discord.com:443 ssl:default [getaddrinfo failed]
2023-04-20T23:14:13 [     116] ERROR   : client          @connect          #605  : Attempting a reconnect in 841.65s
Traceback (most recent call last):
  File "C:\Users\aaaa\AppData\Local\Programs\Python\Python310\lib\site-packages\aiohttp\connector.py", line 1152, in _create_direct_connection
    hosts = await asyncio.shield(host_resolved)
  File "C:\Users\aaaa\AppData\Local\Programs\Python\Python310\lib\site-packages\aiohttp\connector.py", line 874, in _resolve_host
    addrs = await self._resolver.resolve(host, port, family=self._family)
  File "C:\Users\aaaa\AppData\Local\Programs\Python\Python310\lib\site-packages\aiohttp\resolver.py", line 33, in resolve
    infos = await self._loop.getaddrinfo(
  File "C:\Users\aaaa\AppData\Local\Programs\Python\Python310\lib\asyncio\base_events.py", line 863, in getaddrinfo
    return await self.run_in_executor(
  File "C:\Users\aaaa\AppData\Local\Programs\Python\Python310\lib\concurrent\futures\thread.py", line 58, in run
    result = self.fn(*self.args, **self.kwargs)
  File "C:\Users\aaaa\AppData\Local\Programs\Python\Python310\lib\socket.py", line 955, in getaddrinfo
    for res in _socket.getaddrinfo(host, port, family, type, proto, flags):
socket.gaierror: [Errno 11004] getaddrinfo failed

The above exception was the direct cause of the following exception:

Traceback (most recent call last):
  File "C:\Users\aaaa\AppData\Local\Programs\Python\Python310\lib\site-packages\discord\client.py", line 550, in connect
    self.ws = await asyncio.wait_for(coro, timeout=60.0)
  File "C:\Users\aaaa\AppData\Local\Programs\Python\Python310\lib\asyncio\tasks.py", line 445, in wait_for
    return fut.result()
  File "C:\Users\aaaa\AppData\Local\Programs\Python\Python310\lib\site-packages\discord\gateway.py", line 330, in from_client
    gateway = gateway or await client.http.get_gateway()
  File "C:\Users\aaaa\AppData\Local\Programs\Python\Python310\lib\site-packages\discord\http.py", line 2821, in get_gateway
    data = await self.request(Route("GET", "/gateway"))
  File "C:\Users\aaaa\AppData\Local\Programs\Python\Python310\lib\site-packages\discord\http.py", line 280, in request
    async with self.__session.request(
  File "C:\Users\aaaa\AppData\Local\Programs\Python\Python310\lib\site-packages\aiohttp\client.py", line 1141, in __aenter__
    self._resp = await self._coro
  File "C:\Users\aaaa\AppData\Local\Programs\Python\Python310\lib\site-packages\aiohttp\client.py", line 536, in _request
    conn = await self._connector.connect(
  File "C:\Users\aaaa\AppData\Local\Programs\Python\Python310\lib\site-packages\aiohttp\connector.py", line 540, in connect
    proto = await self._create_connection(req, traces, timeout)
  File "C:\Users\aaaa\AppData\Local\Programs\Python\Python310\lib\site-packages\aiohttp\connector.py", line 901, in _create_connection
    _, proto = await self._create_direct_connection(req, traces, timeout)
  File "C:\Users\aaaa\AppData\Local\Programs\Python\Python310\lib\site-packages\aiohttp\connector.py", line 1166, in _create_direct_connection
    raise ClientConnectorError(req.connection_key, exc) from exc
aiohttp.client_exceptions.ClientConnectorError: Cannot connect to host discord.com:443 ssl:default [getaddrinfo failed]
2023-04-20T23:28:14 [     785] ERROR   : client          @connect          #605  : Attempting a reconnect in 510.78s
Traceback (most recent call last):
  File "C:\Users\aaaa\AppData\Local\Programs\Python\Python310\lib\site-packages\aiohttp\connector.py", line 1152, in _create_direct_connection
    hosts = await asyncio.shield(host_resolved)
  File "C:\Users\aaaa\AppData\Local\Programs\Python\Python310\lib\site-packages\aiohttp\connector.py", line 874, in _resolve_host
    addrs = await self._resolver.resolve(host, port, family=self._family)
  File "C:\Users\aaaa\AppData\Local\Programs\Python\Python310\lib\site-packages\aiohttp\resolver.py", line 33, in resolve
    infos = await self._loop.getaddrinfo(
  File "C:\Users\aaaa\AppData\Local\Programs\Python\Python310\lib\asyncio\base_events.py", line 863, in getaddrinfo
    return await self.run_in_executor(
  File "C:\Users\aaaa\AppData\Local\Programs\Python\Python310\lib\concurrent\futures\thread.py", line 58, in run
    result = self.fn(*self.args, **self.kwargs)
  File "C:\Users\aaaa\AppData\Local\Programs\Python\Python310\lib\socket.py", line 955, in getaddrinfo
    for res in _socket.getaddrinfo(host, port, family, type, proto, flags):
socket.gaierror: [Errno 11004] getaddrinfo failed

The above exception was the direct cause of the following exception:

Traceback (most recent call last):
  File "C:\Users\aaaa\AppData\Local\Programs\Python\Python310\lib\site-packages\discord\client.py", line 550, in connect
    self.ws = await asyncio.wait_for(coro, timeout=60.0)
  File "C:\Users\aaaa\AppData\Local\Programs\Python\Python310\lib\asyncio\tasks.py", line 445, in wait_for
    return fut.result()
  File "C:\Users\aaaa\AppData\Local\Programs\Python\Python310\lib\site-packages\discord\gateway.py", line 330, in from_client
    gateway = gateway or await client.http.get_gateway()
  File "C:\Users\aaaa\AppData\Local\Programs\Python\Python310\lib\site-packages\discord\http.py", line 2821, in get_gateway
    data = await self.request(Route("GET", "/gateway"))
  File "C:\Users\aaaa\AppData\Local\Programs\Python\Python310\lib\site-packages\discord\http.py", line 280, in request
    async with self.__session.request(
  File "C:\Users\aaaa\AppData\Local\Programs\Python\Python310\lib\site-packages\aiohttp\client.py", line 1141, in __aenter__
    self._resp = await self._coro
  File "C:\Users\aaaa\AppData\Local\Programs\Python\Python310\lib\site-packages\aiohttp\client.py", line 536, in _request
    conn = await self._connector.connect(
  File "C:\Users\aaaa\AppData\Local\Programs\Python\Python310\lib\site-packages\aiohttp\connector.py", line 540, in connect
    proto = await self._create_connection(req, traces, timeout)
  File "C:\Users\aaaa\AppData\Local\Programs\Python\Python310\lib\site-packages\aiohttp\connector.py", line 901, in _create_connection
    _, proto = await self._create_direct_connection(req, traces, timeout)
  File "C:\Users\aaaa\AppData\Local\Programs\Python\Python310\lib\site-packages\aiohttp\connector.py", line 1166, in _create_direct_connection
    raise ClientConnectorError(req.connection_key, exc) from exc
aiohttp.client_exceptions.ClientConnectorError: Cannot connect to host discord.com:443 ssl:default [getaddrinfo failed]
2023-04-20T23:36:45 [     591] ERROR   : client          @connect          #605  : Attempting a reconnect in 1013.55s
Traceback (most recent call last):
  File "C:\Users\aaaa\AppData\Local\Programs\Python\Python310\lib\site-packages\aiohttp\connector.py", line 1152, in _create_direct_connection
    hosts = await asyncio.shield(host_resolved)
  File "C:\Users\aaaa\AppData\Local\Programs\Python\Python310\lib\site-packages\aiohttp\connector.py", line 874, in _resolve_host
    addrs = await self._resolver.resolve(host, port, family=self._family)
  File "C:\Users\aaaa\AppData\Local\Programs\Python\Python310\lib\site-packages\aiohttp\resolver.py", line 33, in resolve
    infos = await self._loop.getaddrinfo(
  File "C:\Users\aaaa\AppData\Local\Programs\Python\Python310\lib\asyncio\base_events.py", line 863, in getaddrinfo
    return await self.run_in_executor(
  File "C:\Users\aaaa\AppData\Local\Programs\Python\Python310\lib\concurrent\futures\thread.py", line 58, in run
    result = self.fn(*self.args, **self.kwargs)
  File "C:\Users\aaaa\AppData\Local\Programs\Python\Python310\lib\socket.py", line 955, in getaddrinfo
    for res in _socket.getaddrinfo(host, port, family, type, proto, flags):
socket.gaierror: [Errno 11004] getaddrinfo failed

The above exception was the direct cause of the following exception:

Traceback (most recent call last):
  File "C:\Users\aaaa\AppData\Local\Programs\Python\Python310\lib\site-packages\discord\client.py", line 550, in connect
    self.ws = await asyncio.wait_for(coro, timeout=60.0)
  File "C:\Users\aaaa\AppData\Local\Programs\Python\Python310\lib\asyncio\tasks.py", line 445, in wait_for
    return fut.result()
  File "C:\Users\aaaa\AppData\Local\Programs\Python\Python310\lib\site-packages\discord\gateway.py", line 330, in from_client
    gateway = gateway or await client.http.get_gateway()
  File "C:\Users\aaaa\AppData\Local\Programs\Python\Python310\lib\site-packages\discord\http.py", line 2821, in get_gateway
    data = await self.request(Route("GET", "/gateway"))
  File "C:\Users\aaaa\AppData\Local\Programs\Python\Python310\lib\site-packages\discord\http.py", line 280, in request
    async with self.__session.request(
  File "C:\Users\aaaa\AppData\Local\Programs\Python\Python310\lib\site-packages\aiohttp\client.py", line 1141, in __aenter__
    self._resp = await self._coro
  File "C:\Users\aaaa\AppData\Local\Programs\Python\Python310\lib\site-packages\aiohttp\client.py", line 536, in _request
    conn = await self._connector.connect(
  File "C:\Users\aaaa\AppData\Local\Programs\Python\Python310\lib\site-packages\aiohttp\connector.py", line 540, in connect
    proto = await self._create_connection(req, traces, timeout)
  File "C:\Users\aaaa\AppData\Local\Programs\Python\Python310\lib\site-packages\aiohttp\connector.py", line 901, in _create_connection
    _, proto = await self._create_direct_connection(req, traces, timeout)
  File "C:\Users\aaaa\AppData\Local\Programs\Python\Python310\lib\site-packages\aiohttp\connector.py", line 1166, in _create_direct_connection
    raise ClientConnectorError(req.connection_key, exc) from exc
aiohttp.client_exceptions.ClientConnectorError: Cannot connect to host discord.com:443 ssl:default [getaddrinfo failed]
2023-04-20T23:45:13 [     241] INFO    : client          @run              #709  : Received signal to terminate bot and event loop.
2023-04-20T23:45:13 [     242] INFO    : client          @run              #712  : Cleaning up tasks.
2023-04-20T23:45:13 [     243] INFO    : client          @_cancel_tasks    #86   : Cleaning up after 1 tasks.
2023-04-20T23:45:13 [     245] INFO    : client          @_cancel_tasks    #91   : All tasks finished cancelling.
2023-04-20T23:45:13 [     246] INFO    : client          @_cleanup_loop    #111  : Closing the event loop.
